[2024-07-13T03:32:02.673+0000] {local_task_job_runner.py:120} INFO - ::group::Pre task execution logs
[2024-07-13T03:32:02.704+0000] {taskinstance.py:2076} INFO - Dependencies all met for dep_context=non-requeueable deps ti=<TaskInstance: airflow_book_api_pipeline.transform_data manual__2024-07-13T03:26:49.366554+00:00 [queued]>
[2024-07-13T03:32:02.712+0000] {taskinstance.py:2076} INFO - Dependencies all met for dep_context=requeueable deps ti=<TaskInstance: airflow_book_api_pipeline.transform_data manual__2024-07-13T03:26:49.366554+00:00 [queued]>
[2024-07-13T03:32:02.712+0000] {taskinstance.py:2306} INFO - Starting attempt 2 of 2
[2024-07-13T03:32:02.733+0000] {taskinstance.py:2330} INFO - Executing <Task(PythonOperator): transform_data> on 2024-07-13 03:26:49.366554+00:00
[2024-07-13T03:32:02.744+0000] {warnings.py:112} WARNING - /home/***/.local/lib/python3.12/site-packages/***/task/task_runner/standard_task_runner.py:61: DeprecationWarning: This process (pid=1766) is multi-threaded, use of fork() may lead to deadlocks in the child.
  pid = os.fork()

[2024-07-13T03:32:02.745+0000] {standard_task_runner.py:63} INFO - Started process 1768 to run task
[2024-07-13T03:32:02.745+0000] {standard_task_runner.py:90} INFO - Running: ['***', 'tasks', 'run', '***_book_api_pipeline', 'transform_data', 'manual__2024-07-13T03:26:49.366554+00:00', '--job-id', '36', '--raw', '--subdir', 'DAGS_FOLDER/***_book_api_dags.py', '--cfg-path', '/tmp/tmpr14cgkds']
[2024-07-13T03:32:02.747+0000] {standard_task_runner.py:91} INFO - Job 36: Subtask transform_data
[2024-07-13T03:32:02.820+0000] {task_command.py:426} INFO - Running <TaskInstance: airflow_book_api_pipeline.transform_data manual__2024-07-13T03:26:49.366554+00:00 [running]> on host e6b306b9c204
[2024-07-13T03:32:02.980+0000] {taskinstance.py:2648} INFO - Exporting env vars: AIRFLOW_CTX_DAG_OWNER='zainal' AIRFLOW_CTX_DAG_ID='***_book_api_pipeline' AIRFLOW_CTX_TASK_ID='transform_data' AIRFLOW_CTX_EXECUTION_DATE='2024-07-13T03:26:49.366554+00:00' AIRFLOW_CTX_TRY_NUMBER='2' AIRFLOW_CTX_DAG_RUN_ID='manual__2024-07-13T03:26:49.366554+00:00'
[2024-07-13T03:32:02.981+0000] {taskinstance.py:430} INFO - ::endgroup::
[2024-07-13T03:32:03.234+0000] {taskinstance.py:441} INFO - ::group::Post task execution logs
[2024-07-13T03:32:03.234+0000] {taskinstance.py:2905} ERROR - Task failed with exception
Traceback (most recent call last):
  File "/home/airflow/.local/lib/python3.12/site-packages/airflow/models/taskinstance.py", line 465, in _execute_task
    result = _execute_callable(context=context, **execute_callable_kwargs)
             ^^^^^^^^^^^^^^^^^^^^^^^^^^^^^^^^^^^^^^^^^^^^^^^^^^^^^^^^^^^^^
  File "/home/airflow/.local/lib/python3.12/site-packages/airflow/models/taskinstance.py", line 432, in _execute_callable
    return execute_callable(context=context, **execute_callable_kwargs)
           ^^^^^^^^^^^^^^^^^^^^^^^^^^^^^^^^^^^^^^^^^^^^^^^^^^^^^^^^^^^^
  File "/home/airflow/.local/lib/python3.12/site-packages/airflow/models/baseoperator.py", line 401, in wrapper
    return func(self, *args, **kwargs)
           ^^^^^^^^^^^^^^^^^^^^^^^^^^^
  File "/home/airflow/.local/lib/python3.12/site-packages/airflow/operators/python.py", line 235, in execute
    return_value = self.execute_callable()
                   ^^^^^^^^^^^^^^^^^^^^^^^
  File "/home/airflow/.local/lib/python3.12/site-packages/airflow/operators/python.py", line 252, in execute_callable
    return self.python_callable(*self.op_args, **self.op_kwargs)
           ^^^^^^^^^^^^^^^^^^^^^^^^^^^^^^^^^^^^^^^^^^^^^^^^^^^^^
  File "/opt/airflow/dags/airflow_book_api_dags.py", line 22, in transform_data
    availability = book['availability']['status']
                   ~~~~^^^^^^^^^^^^^^^^
KeyError: 'availability'
[2024-07-13T03:32:03.244+0000] {taskinstance.py:1206} INFO - Marking task as FAILED. dag_id=***_book_api_pipeline, task_id=transform_data, run_id=manual__2024-07-13T03:26:49.366554+00:00, execution_date=20240713T032649, start_date=20240713T033202, end_date=20240713T033203
[2024-07-13T03:32:03.263+0000] {standard_task_runner.py:110} ERROR - Failed to execute job 36 for task transform_data ('availability'; 1768)
[2024-07-13T03:32:03.301+0000] {local_task_job_runner.py:240} INFO - Task exited with return code 1
[2024-07-13T03:32:03.320+0000] {taskinstance.py:3503} INFO - 0 downstream tasks scheduled from follow-on schedule check
[2024-07-13T03:32:03.330+0000] {local_task_job_runner.py:222} INFO - ::endgroup::
