[2024-07-13T01:38:46.016+0000] {local_task_job_runner.py:120} INFO - ::group::Pre task execution logs
[2024-07-13T01:38:46.044+0000] {taskinstance.py:2076} INFO - Dependencies all met for dep_context=non-requeueable deps ti=<TaskInstance: airflow_book_api_pipeline.create_table scheduled__2024-07-12T00:00:00+00:00 [queued]>
[2024-07-13T01:38:46.049+0000] {taskinstance.py:2076} INFO - Dependencies all met for dep_context=requeueable deps ti=<TaskInstance: airflow_book_api_pipeline.create_table scheduled__2024-07-12T00:00:00+00:00 [queued]>
[2024-07-13T01:38:46.049+0000] {taskinstance.py:2306} INFO - Starting attempt 1 of 2
[2024-07-13T01:38:46.065+0000] {taskinstance.py:2330} INFO - Executing <Task(PythonOperator): create_table> on 2024-07-12 00:00:00+00:00
[2024-07-13T01:38:46.073+0000] {warnings.py:112} WARNING - /home/***/.local/lib/python3.12/site-packages/***/task/task_runner/standard_task_runner.py:61: DeprecationWarning: This process (pid=194) is multi-threaded, use of fork() may lead to deadlocks in the child.
  pid = os.fork()

[2024-07-13T01:38:46.074+0000] {standard_task_runner.py:63} INFO - Started process 196 to run task
[2024-07-13T01:38:46.075+0000] {standard_task_runner.py:90} INFO - Running: ['***', 'tasks', 'run', '***_book_api_pipeline', 'create_table', 'scheduled__2024-07-12T00:00:00+00:00', '--job-id', '9', '--raw', '--subdir', 'DAGS_FOLDER/***_book_api_dags.py', '--cfg-path', '/tmp/tmpqnnb_esn']
[2024-07-13T01:38:46.076+0000] {standard_task_runner.py:91} INFO - Job 9: Subtask create_table
[2024-07-13T01:38:46.128+0000] {task_command.py:426} INFO - Running <TaskInstance: airflow_book_api_pipeline.create_table scheduled__2024-07-12T00:00:00+00:00 [running]> on host e6b306b9c204
[2024-07-13T01:38:46.282+0000] {taskinstance.py:2648} INFO - Exporting env vars: AIRFLOW_CTX_DAG_OWNER='zainal' AIRFLOW_CTX_DAG_ID='***_book_api_pipeline' AIRFLOW_CTX_TASK_ID='create_table' AIRFLOW_CTX_EXECUTION_DATE='2024-07-12T00:00:00+00:00' AIRFLOW_CTX_TRY_NUMBER='1' AIRFLOW_CTX_DAG_RUN_ID='scheduled__2024-07-12T00:00:00+00:00'
[2024-07-13T01:38:46.283+0000] {taskinstance.py:430} INFO - ::endgroup::
[2024-07-13T01:38:46.296+0000] {taskinstance.py:441} INFO - ::group::Post task execution logs
[2024-07-13T01:38:46.303+0000] {taskinstance.py:2905} ERROR - Task failed with exception
Traceback (most recent call last):
  File "/home/airflow/.local/lib/python3.12/site-packages/airflow/models/taskinstance.py", line 465, in _execute_task
    result = _execute_callable(context=context, **execute_callable_kwargs)
             ^^^^^^^^^^^^^^^^^^^^^^^^^^^^^^^^^^^^^^^^^^^^^^^^^^^^^^^^^^^^^
  File "/home/airflow/.local/lib/python3.12/site-packages/airflow/models/taskinstance.py", line 432, in _execute_callable
    return execute_callable(context=context, **execute_callable_kwargs)
           ^^^^^^^^^^^^^^^^^^^^^^^^^^^^^^^^^^^^^^^^^^^^^^^^^^^^^^^^^^^^
  File "/home/airflow/.local/lib/python3.12/site-packages/airflow/models/baseoperator.py", line 401, in wrapper
    return func(self, *args, **kwargs)
           ^^^^^^^^^^^^^^^^^^^^^^^^^^^
  File "/home/airflow/.local/lib/python3.12/site-packages/airflow/operators/python.py", line 235, in execute
    return_value = self.execute_callable()
                   ^^^^^^^^^^^^^^^^^^^^^^^
  File "/home/airflow/.local/lib/python3.12/site-packages/airflow/operators/python.py", line 252, in execute_callable
    return self.python_callable(*self.op_args, **self.op_kwargs)
           ^^^^^^^^^^^^^^^^^^^^^^^^^^^^^^^^^^^^^^^^^^^^^^^^^^^^^
  File "/opt/airflow/dags/airflow_book_api_dags.py", line 35, in create_table
    snowflake_hook.run(create_table_query)
  File "/home/airflow/.local/lib/python3.12/site-packages/airflow/providers/snowflake/hooks/snowflake.py", line 392, in run
    with closing(self.get_conn()) as conn:
                 ^^^^^^^^^^^^^^^
  File "/home/airflow/.local/lib/python3.12/site-packages/airflow/providers/snowflake/hooks/snowflake.py", line 289, in get_conn
    conn_config = self._get_conn_params
                  ^^^^^^^^^^^^^^^^^^^^^
  File "/usr/local/lib/python3.12/functools.py", line 995, in __get__
    val = self.func(instance)
          ^^^^^^^^^^^^^^^^^^^
  File "/home/airflow/.local/lib/python3.12/site-packages/airflow/providers/snowflake/hooks/snowflake.py", line 188, in _get_conn_params
    conn = self.get_connection(self.snowflake_conn_id)  # type: ignore[attr-defined]
           ^^^^^^^^^^^^^^^^^^^^^^^^^^^^^^^^^^^^^^^^^^^
  File "/home/airflow/.local/lib/python3.12/site-packages/airflow/hooks/base.py", line 83, in get_connection
    conn = Connection.get_connection_from_secrets(conn_id)
           ^^^^^^^^^^^^^^^^^^^^^^^^^^^^^^^^^^^^^^^^^^^^^^^
  File "/home/airflow/.local/lib/python3.12/site-packages/airflow/models/connection.py", line 519, in get_connection_from_secrets
    raise AirflowNotFoundException(f"The conn_id `{conn_id}` isn't defined")
airflow.exceptions.AirflowNotFoundException: The conn_id `snowflake_default` isn't defined
[2024-07-13T01:38:46.322+0000] {taskinstance.py:1206} INFO - Marking task as UP_FOR_RETRY. dag_id=***_book_api_pipeline, task_id=create_table, run_id=scheduled__2024-07-12T00:00:00+00:00, execution_date=20240712T000000, start_date=20240713T013846, end_date=20240713T013846
[2024-07-13T01:38:46.354+0000] {standard_task_runner.py:110} ERROR - Failed to execute job 9 for task create_table (The conn_id `snowflake_default` isn't defined; 196)
[2024-07-13T01:38:46.371+0000] {local_task_job_runner.py:240} INFO - Task exited with return code 1
[2024-07-13T01:38:46.391+0000] {taskinstance.py:3503} INFO - 0 downstream tasks scheduled from follow-on schedule check
[2024-07-13T01:38:46.398+0000] {local_task_job_runner.py:222} INFO - ::endgroup::
