[2024-07-13T02:31:01.501+0000] {local_task_job_runner.py:120} INFO - ::group::Pre task execution logs
[2024-07-13T02:31:01.531+0000] {taskinstance.py:2076} INFO - Dependencies all met for dep_context=non-requeueable deps ti=<TaskInstance: airflow_book_api_pipeline.insert_to_snowflake manual__2024-07-13T02:30:46.277051+00:00 [queued]>
[2024-07-13T02:31:01.539+0000] {taskinstance.py:2076} INFO - Dependencies all met for dep_context=requeueable deps ti=<TaskInstance: airflow_book_api_pipeline.insert_to_snowflake manual__2024-07-13T02:30:46.277051+00:00 [queued]>
[2024-07-13T02:31:01.539+0000] {taskinstance.py:2306} INFO - Starting attempt 1 of 2
[2024-07-13T02:31:01.565+0000] {taskinstance.py:2330} INFO - Executing <Task(PythonOperator): insert_to_snowflake> on 2024-07-13 02:30:46.277051+00:00
[2024-07-13T02:31:01.586+0000] {warnings.py:112} WARNING - /home/***/.local/lib/python3.12/site-packages/***/task/task_runner/standard_task_runner.py:61: DeprecationWarning: This process (pid=933) is multi-threaded, use of fork() may lead to deadlocks in the child.
  pid = os.fork()

[2024-07-13T02:31:01.597+0000] {standard_task_runner.py:63} INFO - Started process 935 to run task
[2024-07-13T02:31:01.588+0000] {standard_task_runner.py:90} INFO - Running: ['***', 'tasks', 'run', '***_book_api_pipeline', 'insert_to_snowflake', 'manual__2024-07-13T02:30:46.277051+00:00', '--job-id', '27', '--raw', '--subdir', 'DAGS_FOLDER/***_book_api_dags.py', '--cfg-path', '/tmp/tmpsj7wnqoc']
[2024-07-13T02:31:01.599+0000] {standard_task_runner.py:91} INFO - Job 27: Subtask insert_to_snowflake
[2024-07-13T02:31:01.710+0000] {task_command.py:426} INFO - Running <TaskInstance: airflow_book_api_pipeline.insert_to_snowflake manual__2024-07-13T02:30:46.277051+00:00 [running]> on host e6b306b9c204
[2024-07-13T02:31:01.911+0000] {taskinstance.py:2648} INFO - Exporting env vars: AIRFLOW_CTX_DAG_OWNER='zainal' AIRFLOW_CTX_DAG_ID='***_book_api_pipeline' AIRFLOW_CTX_TASK_ID='insert_to_snowflake' AIRFLOW_CTX_EXECUTION_DATE='2024-07-13T02:30:46.277051+00:00' AIRFLOW_CTX_TRY_NUMBER='1' AIRFLOW_CTX_DAG_RUN_ID='manual__2024-07-13T02:30:46.277051+00:00'
[2024-07-13T02:31:01.912+0000] {taskinstance.py:430} INFO - ::endgroup::
[2024-07-13T02:31:01.991+0000] {base.py:84} INFO - Using connection ID 'snowflake-conn' for task execution.
[2024-07-13T02:31:01.993+0000] {connection.py:399} INFO - Snowflake Connector for Python Version: 3.10.1, Python Version: 3.12.4, Platform: Linux-6.5.0-1022-azure-x86_64-with-glibc2.36
[2024-07-13T02:31:01.996+0000] {connection.py:1239} INFO - This connection is in OCSP Fail Open Mode. TLS Certificates would be checked for validity and revocation status. Any other Certificate Revocation related exceptions or OCSP Responder failures would be disregarded in favor of connectivity.
[2024-07-13T02:31:02.508+0000] {cursor.py:1149} INFO - Number of results in first chunk: 1
[2024-07-13T02:31:02.508+0000] {sql.py:487} INFO - Running statement: INSERT INTO PROJECTS_DB.PUBLIC.book_table (title, author, publish_date) VALUES (%s, %s, %s), parameters: ['Frankenstein or The Modern Prometheus', 'Mary Shelley', 1818]
[2024-07-13T02:31:02.569+0000] {connection.py:762} INFO - closed
[2024-07-13T02:31:02.586+0000] {connection.py:768} INFO - No async queries seem to be running, deleting session
[2024-07-13T02:31:02.610+0000] {taskinstance.py:441} INFO - ::group::Post task execution logs
[2024-07-13T02:31:02.611+0000] {taskinstance.py:2905} ERROR - Task failed with exception
Traceback (most recent call last):
  File "/home/airflow/.local/lib/python3.12/site-packages/airflow/models/taskinstance.py", line 465, in _execute_task
    result = _execute_callable(context=context, **execute_callable_kwargs)
             ^^^^^^^^^^^^^^^^^^^^^^^^^^^^^^^^^^^^^^^^^^^^^^^^^^^^^^^^^^^^^
  File "/home/airflow/.local/lib/python3.12/site-packages/airflow/models/taskinstance.py", line 432, in _execute_callable
    return execute_callable(context=context, **execute_callable_kwargs)
           ^^^^^^^^^^^^^^^^^^^^^^^^^^^^^^^^^^^^^^^^^^^^^^^^^^^^^^^^^^^^
  File "/home/airflow/.local/lib/python3.12/site-packages/airflow/models/baseoperator.py", line 401, in wrapper
    return func(self, *args, **kwargs)
           ^^^^^^^^^^^^^^^^^^^^^^^^^^^
  File "/home/airflow/.local/lib/python3.12/site-packages/airflow/operators/python.py", line 235, in execute
    return_value = self.execute_callable()
                   ^^^^^^^^^^^^^^^^^^^^^^^
  File "/home/airflow/.local/lib/python3.12/site-packages/airflow/operators/python.py", line 252, in execute_callable
    return self.python_callable(*self.op_args, **self.op_kwargs)
           ^^^^^^^^^^^^^^^^^^^^^^^^^^^^^^^^^^^^^^^^^^^^^^^^^^^^^
  File "/opt/airflow/dags/airflow_book_api_dags.py", line 45, in insert_to_snowflake
    snowflake_hook.run(insert_stmt, parameters=record)
  File "/home/airflow/.local/lib/python3.12/site-packages/airflow/providers/snowflake/hooks/snowflake.py", line 398, in run
    self._run_command(cur, sql_statement, parameters)  # type: ignore[attr-defined]
    ^^^^^^^^^^^^^^^^^^^^^^^^^^^^^^^^^^^^^^^^^^^^^^^^^
  File "/home/airflow/.local/lib/python3.12/site-packages/airflow/providers/common/sql/hooks/sql.py", line 490, in _run_command
    cur.execute(sql_statement, parameters)
  File "/home/airflow/.local/lib/python3.12/site-packages/snowflake/connector/cursor.py", line 1080, in execute
    Error.errorhandler_wrapper(self.connection, self, error_class, errvalue)
  File "/home/airflow/.local/lib/python3.12/site-packages/snowflake/connector/errors.py", line 290, in errorhandler_wrapper
    handed_over = Error.hand_to_other_handler(
                  ^^^^^^^^^^^^^^^^^^^^^^^^^^^^
  File "/home/airflow/.local/lib/python3.12/site-packages/snowflake/connector/errors.py", line 345, in hand_to_other_handler
    cursor.errorhandler(connection, cursor, error_class, error_value)
  File "/home/airflow/.local/lib/python3.12/site-packages/snowflake/connector/errors.py", line 221, in default_errorhandler
    raise error_class(
snowflake.connector.errors.ProgrammingError: 002023 (22000): 01b5a1b7-0000-c78a-0001-1bbe0002a19e: SQL compilation error:
Expression type does not match column data type, expecting DATE but got NUMBER(4,0) for column PUBLISH_DATE
[2024-07-13T02:31:02.618+0000] {taskinstance.py:1206} INFO - Marking task as UP_FOR_RETRY. dag_id=***_book_api_pipeline, task_id=insert_to_snowflake, run_id=manual__2024-07-13T02:30:46.277051+00:00, execution_date=20240713T023046, start_date=20240713T023101, end_date=20240713T023102
[2024-07-13T02:31:02.636+0000] {standard_task_runner.py:110} ERROR - Failed to execute job 27 for task insert_to_snowflake (002023 (22000): 01b5a1b7-0000-c78a-0001-1bbe0002a19e: SQL compilation error:
Expression type does not match column data type, expecting DATE but got NUMBER(4,0) for column PUBLISH_DATE; 935)
[2024-07-13T02:31:02.672+0000] {local_task_job_runner.py:240} INFO - Task exited with return code 1
[2024-07-13T02:31:02.685+0000] {taskinstance.py:3503} INFO - 0 downstream tasks scheduled from follow-on schedule check
[2024-07-13T02:31:02.691+0000] {local_task_job_runner.py:222} INFO - ::endgroup::
